<?xml version="1.0"?>

<robot xmlns:xacro="https://www.ros.org/wiki/xacro">

    <xacro:include filename="$(find kobuki_description)/model/wheels/kobuki_wheels.gazebo.xacro"/>

    <xacro:macro name="kobuki_wheel" params="prefix parent *joint_origin">
        <joint name="${prefix}_wheel_joint" type="continuous">
            <xacro:insert_block name="joint_origin"/>
            <parent link="${parent}"/>
            <child link="${prefix}_wheel_link"/>
            <limit effort="50000" velocity="10"/>
            <dynamics damping="1.0" friction="1.0"/>
            <axis xyz="0 0 1"/>
        </joint>

        <link name="${prefix}_wheel_link">
            <visual>
                <origin xyz="0 0 0" rpy="0 0 0"/>
                <geometry>
                    <mesh filename="file://$(find kobuki_description)/meshes/wheel.dae"/>
                </geometry>
            </visual>
        
            <collision>
                <geometry>
                    <cylinder length="0.0206" radius="0.0352"/>
                </geometry>
                <origin rpy="0 0 0" xyz="0 0 0"/>
            </collision>
        
            <inertial>
                <mass value="0.01" />
                <origin xyz="0 0 0" />
                <inertia ixx="0.001" ixy="0.0" ixz="0.0"
                         iyy="0.001" iyz="0.0"
                         izz="0.001" />
            </inertial>
        </link>
    </xacro:macro>

</robot>